mplus_output/uni-43-SAGE (Russia)_W1.out
Mplus VERSION 8.1 (Mac)
MUTHEN & MUTHEN
04/23/2020  10:56 PM

INPUT INSTRUCTIONS

  DATA:
  FILE = "uni-43-SAGE (Russia)_W1.dat";

  VARIABLE:
  NAMES = mplusid UANI UIWR UIWR2 UIWR3 UDIGF UDIGB;
   MISSING=.;
   CATEGORICAL ARE all; idvariable = mplusid;
  ANALYSIS:
  estimator = wlsmv; coverage=0;
  MODEL:
  g by UIWR * ;
   g by UANI * ;
   g by UIWR2 * ;
   g by UIWR3 * ;
   g by UDIGF * ;
   g by UDIGB * ;
   g @ 1;

  OUTPUT:
  standardized; svalues;



INPUT READING TERMINATED NORMALLY




SUMMARY OF ANALYSIS

Number of groups                                                 1
Number of observations                                        4323

Number of dependent variables                                    6
Number of independent variables                                  0
Number of continuous latent variables                            1

Observed dependent variables

  Binary and ordered categorical (ordinal)
   UANI        UIWR        UIWR2       UIWR3       UDIGF       UDIGB

Continuous latent variables
   G

Variables with special functions

  ID variable           MPLUSID

Estimator                                                    WLSMV
Maximum number of iterations                                  1000
Convergence criterion                                    0.500D-04
Maximum number of steepest descent iterations                   20
Maximum number of iterations for H1                           2000
Convergence criterion for H1                             0.100D-03
Parameterization                                             DELTA
Link                                                        PROBIT

Input data file(s)
  uni-43-SAGE (Russia)_W1.dat

Input data format  FREE


SUMMARY OF DATA

     Number of missing data patterns            18


COVARIANCE COVERAGE OF DATA

Minimum covariance coverage value   0.000


     PROPORTION OF DATA PRESENT


           Covariance Coverage
              UANI          UIWR          UIWR2         UIWR3         UDIGF
              ________      ________      ________      ________      ________
 UANI           0.947
 UIWR           0.921         0.960
 UIWR2          0.916         0.954         0.954
 UIWR3          0.906         0.943         0.944         0.944
 UDIGF          0.947         0.960         0.954         0.944         1.000
 UDIGB          0.873         0.905         0.900         0.891         0.908


           Covariance Coverage
              UDIGB
              ________
 UDIGB          0.908


UNIVARIATE PROPORTIONS AND COUNTS FOR CATEGORICAL VARIABLES

    UANI
      Category 1    0.059          241.000
      Category 2    0.087          358.000
      Category 3    0.228          933.000
      Category 4    0.264         1081.000
      Category 5    0.165          675.000
      Category 6    0.098          401.000
      Category 7    0.054          222.000
      Category 8    0.027          109.000
      Category 9    0.011           43.000
      Category 10    0.008           32.000
    UIWR
      Category 1    0.007           30.000
      Category 2    0.007           29.000
      Category 3    0.028          115.000
      Category 4    0.092          380.000
      Category 5    0.172          715.000
      Category 6    0.455         1888.000
      Category 7    0.137          567.000
      Category 8    0.066          274.000
      Category 9    0.025          103.000
      Category 10    0.012           50.000
    UIWR2
      Category 1    0.006           26.000
      Category 2    0.002            9.000
      Category 3    0.009           38.000
      Category 4    0.045          184.000
      Category 5    0.115          474.000
      Category 6    0.384         1585.000
      Category 7    0.201          831.000
      Category 8    0.137          565.000
      Category 9    0.060          248.000
      Category 10    0.040          165.000
    UIWR3
      Category 1    0.010           41.000
      Category 2    0.002            8.000
      Category 3    0.013           55.000
      Category 4    0.039          158.000
      Category 5    0.082          335.000
      Category 6    0.294         1198.000
      Category 7    0.186          759.000
      Category 8    0.167          683.000
      Category 9    0.104          423.000
      Category 10    0.103          419.000
    UDIGF
      Category 1    0.092          397.000
      Category 2    0.053          230.000
      Category 3    0.185          798.000
      Category 4    0.274         1183.000
      Category 5    0.229          989.000
      Category 6    0.111          481.000
      Category 7    0.037          160.000
      Category 8    0.020           85.000
    UDIGB
      Category 1    0.011           43.000
      Category 2    0.071          277.000
      Category 3    0.276         1084.000
      Category 4    0.311         1220.000
      Category 5    0.196          769.000
      Category 6    0.090          352.000
      Category 7    0.027          105.000
      Category 8    0.019           76.000



THE MODEL ESTIMATION TERMINATED NORMALLY



MODEL FIT INFORMATION

Number of Free Parameters                       56

Chi-Square Test of Model Fit

          Value                           2895.314*
          Degrees of Freedom                     9
          P-Value                           0.0000

*   The chi-square value for MLM, MLMV, MLR, ULSMV, WLSM and WLSMV cannot be used
    for chi-square difference testing in the regular way.  MLM, MLR and WLSM
    chi-square difference testing is described on the Mplus website.  MLMV, WLSMV,
    and ULSMV difference testing is done using the DIFFTEST option.

RMSEA (Root Mean Square Error Of Approximation)

          Estimate                           0.272
          90 Percent C.I.                    0.264  0.281
          Probability RMSEA <= .05           0.000

CFI/TLI

          CFI                                0.951
          TLI                                0.918

Chi-Square Test of Model Fit for the Baseline Model

          Value                          58501.822
          Degrees of Freedom                    15
          P-Value                           0.0000

SRMR (Standardized Root Mean Square Residual)

          Value                              0.046

Optimum Function Value for Weighted Least-Squares Estimator

          Value                     0.21340449D+00



MODEL RESULTS

                                                    Two-Tailed
                    Estimate       S.E.  Est./S.E.    P-Value

 G        BY
    UIWR               0.771      0.006    129.938      0.000
    UANI               0.557      0.010     56.245      0.000
    UIWR2              0.930      0.004    234.342      0.000
    UIWR3              0.876      0.004    204.981      0.000
    UDIGF              0.770      0.006    121.319      0.000
    UDIGB              0.741      0.007    102.046      0.000

 Thresholds
    UANI$1            -1.564      0.031    -49.912      0.000
    UANI$2            -1.053      0.024    -43.698      0.000
    UANI$3            -0.321      0.020    -16.084      0.000
    UANI$4             0.353      0.020     17.637      0.000
    UANI$5             0.852      0.022     38.038      0.000
    UANI$6             1.286      0.027     48.040      0.000
    UANI$7             1.696      0.034     49.603      0.000
    UANI$8             2.090      0.047     44.809      0.000
    UANI$9             2.417      0.064     37.723      0.000
    UIWR$1            -2.446      0.066    -37.288      0.000
    UIWR$2            -2.191      0.051    -43.124      0.000
    UIWR$3            -1.729      0.035    -49.751      0.000
    UIWR$4            -1.110      0.025    -45.308      0.000
    UIWR$5            -0.508      0.020    -24.913      0.000
    UIWR$6             0.708      0.021     33.190      0.000
    UIWR$7             1.265      0.026     48.078      0.000
    UIWR$8             1.788      0.036     49.299      0.000
    UIWR$9             2.256      0.054     41.747      0.000
